Workbook

Sheet Producto
B2: CAMPO | C2: FILTRO SELECCIÓN
B3: MONEDA | C3: Nacional
B4: FORMA DE VENTAS | C4: TODAS
B5: GIRO DE LA UBICACIÓN | C5: Casa Habitaciòn
B6: NÚMERO DE NIVELES | C6: TODOS
B7: TIPO PRIMER RIESGO | C7: Ninguno
B8: ENTIDAD | C8: TODAS
B9: SUBTIPO DE SEGURO | C9: TODOS
B10: TIPO DE BIEN | C10: Contenidos; Contenidos y Edificio; Edificio
B11: COBERTURAS | C11: Incendio, rayo y explosión; Remoción de Escombros; Gastos Extras para Casa Habitación

Sheet Emisión
A1: MONEDA | B1: FORMA DE VENTA | C1: GIRO DE LA UBICACIÓN | D1: ENTIDAD | E1: SUBTIPO DE SEGURO | F1: NÚMERO DE NIVELES | G1: TIPO PRIMER RIESGO | H1: NÚMERO DE UBICACIONES | I1: PRIMA EMITIDA | J1: PRIMA RETENIDA | K1: PRIMA DEVENGADA EN EL EJERCICIO | L1: PRIMA DEVENGADA ACUMULADA | M1: COMISIÓN DIRECTA | N1: VALORES TOTALES EDIFICIO | O1: VALORES TOTALES CONTENIDO | P1: VALORES TOTALES EXISTENCIAS | Q1: VALORES TOTALES PÉRDIDAS CONSECUENCIALES | R1: LÍMITE MÁXIMO DE RESPONSABILIDAD | S1: AÑO
A2: Nacional | B2: Agentes Persona Física | C2: Casa Habitaciòn | D2: Aguascalientes | E2: Otro | F2: 1 | G2: Ninguno | H2: 661 | I2: 156517.17 | J2: 92740.51 | K2: 150650.28 | L2: 236649.72 | M2: 30635.75 | N2: 974286065 | O2: 284409126 | P2: 0 | Q2: 76121640 | R2: 1334816831 | S2: 2024
A3: Nacional | B3: Agentes Persona Física | C3: Casa Habitaciòn | D3: Aguascalientes | E3: Otro | F3: 2 | G3: Ninguno | H3: 1189 | I3: 533159.18 | J3: 426059.34 | K3: 502946.67 | L3: 760788.74 | M3: 102213.04 | N3: 3098256397 | O3: 798227629 | P3: 0 | Q3: 216400621 | R3: 4112884647 | S3: 2024
A4: Nacional | B4: Agentes Persona Física | C4: Casa Habitaciòn | D4: Aguascalientes | E4: Otro | F4: 3 | G4: Ninguno | H4: 70 | I4: 27028.27 | J4: 17665.73 | K4: 25068.08 | L4: 35989.93 | M4: 6143.12 | N4: 206024824 | O4: 69137053 | P4: 0 | Q4: 21659941 | R4: 296821818 | S4: 2024
A5: Nacional | B5: Agentes Persona Física | C5: Casa Habitaciòn | D5: Aguascalientes | E5: Otro | F5: 4 | G5: Ninguno | H5: 8 | I5: 3929.22 | J5: 1681.34 | K5: 3261 | L5: 4833.64 | M5: 723.18 | N5: 32424374 | O5: 760237 | P5: 0 | Q5: 366000 | R5: 33550611 | S5: 2024
A6: Nacional | B6: Agentes Persona Física | C6: Casa Habitaciòn | D6: Aguascalientes | E6: Otro | F6: 5 | G6: Ninguno | H6: 56 | I6: 16042.99 | J6: 12834.42 | K6: 15636.19 | L6: 21616.72 | M6: 4020 | N6: 197217000 | O6: 53480000 | P6: 0 | Q6: 6570000 | R6: 257267000 | S6: 2024
A7: Nacional | B7: Agentes Persona Física | C7: Casa Habitaciòn | D7: Aguascalientes | E7: Otro | F7: 6 | G7: Ninguno | H7: 7 | I7: 27689.96 | J7: 3838.51 | K7: 16988.78 | L7: 17421.12 | M7: 6926.49 | N7: 255780000 | O7: 4650000 | P7: 0 | Q7: 1220000 | R7: 261650000 | S7: 2024
A8: Nacional | B8: Agentes Persona Física | C8: Casa Habitaciòn | D8: Aguascalientes | E8: Otro | F8: 7 | G8: Ninguno | H8: 2 | I8: 0 | J8: 0 | K8: 6592.73 | L8: 19563.8 | M8: 0 | N8: 183633094 | O8: 0 | P8: 0 | Q8: 18363310 | R8: 201996404 | S8: 2024
A9: Nacional | B9: Agentes Persona Física | C9: Casa Habitaciòn | D9: Aguascalientes | E9: Otro | F9: 10 | G9: Ninguno | H9: 1 | I9: 0 | J9: 0 | K9: 0 | L9: 0 | M9: 0 | N9: 4500000 | O9: 600000 | P9: 0 | Q9: 262500 | R9: 5362500 | S9: 2024
A10: Nacional | B10: Agentes Persona Física | C10: Casa Habitaciòn | D10: Aguascalientes | E10: Otro | F10: 15 | G10: Ninguno | H10: 3 | I10: 4780.5 | J10: 2390.25 | K10: 2390.78 | L10: 4505.78 | M10: 1084 | N10: 14639172 | O10: 300000 | P10: 0 | Q10: 1577251 | R10: 16516423 | S10: 2024
A11: Nacional | B11: Agentes Persona Física | C11: Casa Habitaciòn | D11: Aguascalientes | E11: Otro | F11: 53 | G11: Ninguno | H11: 2 | I11: 0 | J11: 0 | K11: 668.76 | L11: 990.95 | M11: 0 | N11: 183186 | O11: 1008000 | P11: 0 | Q11: 73348 | R11: 1264534 | S11: 2024
A12: Nacional | B12: Agentes Persona Física | C12: Casa Habitaciòn | D12: Aguascalientes | E12: Pymes | F12: 1 | G12: Ninguno | H12: 4 | I12: 23563.62 | J12: 2920.78 | K12: 29349.54 | L12: 58967.8 | M12: 3304.42 | N12: 588000000 | O12: 93600000 | P12: 0 | Q12: 33950000 | R12: 715550000 | S12: 2024
A13: Nacional | B13: Agentes Persona Física | C13: Casa Habitaciòn | D13: Aguascalientes | E13: Pymes | F13: 2 | G13: Ninguno | H13: 2 | I13: 4469.64 | J13: 1787.85 | K13: 2076.75 | L13: 2076.75 | M13: 759.84 | N13: 21000000 | O13: 18180030 | P13: 0 | Q13: 1100000 | R13: 40280030 | S13: 2024
... A10013: Nacional | B10013: Otros Canales de Venta Masiva | C10013: Casa Habitaciòn | D10013: Zacatecas | E10013: Otro | F10013: 1 | G10013: Ninguno | H10013: 5 | I10013: 609.14 | J10013: 609.14 | K10013: 1326.51 | L10013: 2224.54 | M10013: 61 | N10013: 30000000 | O10013: 21000000 | P10013: 0 | Q10013: 3400000 | R10013: 54400000 | S10013: 2021
A10014: Nacional | B10014: Agentes Persona Física | C10014: Casa Habitaciòn | D10014: Aguascalientes | E10014: Otro | F10014: 1 | G10014: Ninguno | H10014: 1067 | I10014: 275434.71 | J10014: 138698.15 | K10014: 221809.04 | M10014: 45770 | N10014: 2206340706 | O10014: 630250942 | P10014: 0 | Q10014: 468283089 | R10014: 3304874737 | S10014: 2020
A10015: Nacional | B10015: Agentes Persona Física | C10015: Casa Habitaciòn | D10015: Aguascalientes | E10015: Otro | F10015: 2 | G10015: Ninguno | H10015: 1031 | I10015: 327307.27 | J10015: 375564.68 | K10015: 310907.37 | M10015: 43489 | N10015: 2769641446 | O10015: 571211861 | P10015: 0 | Q10015: 300460957 | R10015: 3641314264 | S10015: 2020
A10016: Nacional | B10016: Agentes Persona Física | C10016: Casa Habitaciòn | D10016: Aguascalientes | E10016: Otro | F10016: 3 | G10016: Ninguno | H10016: 36 | I10016: 11803.3 | J10016: 11514.08 | K10016: 4900.04 | M10016: 2317 | N10016: 77693960 | O10016: 21165721 | P10016: 0 | Q10016: 5224407 | R10016: 104084088 | S10016: 2020
A10017: Nacional | B10017: Agentes Persona Física | C10017: Casa Habitaciòn | D10017: Aguascalientes | E10017: Otro | F10017: 4 | G10017: Ninguno | H10017: 3 | I10017: 2002.14 | J10017: 972.97 | K10017: 1721.55 | M10017: 303 | N10017: 17250000 | O10017: 0 | P10017: 0 | Q10017: 0 | R10017: 17250000 | S10017: 2020
A10018: Nacional | B10018: Agentes Persona Física | C10018: Casa Habitaciòn | D10018: Aguascalientes | E10018: Otro | F10018: 5 | G10018: Ninguno | H10018: 23 | I10018: 20531.21 | J10018: 13531.93 | K10018: 13571.01 | M10018: 5122 | N10018: 155198433 | O10018: 19185000 | P10018: 0 | Q10018: 13737843 | R10018: 188121276 | S10018: 2020
A10019: Nacional | B10019: Agentes Persona Física | C10019: Casa Habitaciòn | D10019: Aguascalientes | E10019: Otro | F10019: 6 | G10019: Ninguno | H10019: 3 | I10019: 497.71 | J10019: 198.26 | K10019: 623.42 | M10019: 75 | N10019: 6000000 | O10019: 1000000 | P10019: 0 | Q10019: 1500000 | R10019: 8500000 | S10019: 2020
A10020: Nacional | B10020: Agentes Persona Física | C10020: Casa Habitaciòn | D10020: Aguascalientes | E10020: Otro | F10020: 8 | G10020: Ninguno | H10020: 1 | I10020: 0 | J10020: 0 | K10020: 0 | M10020: 0 | N10020: 61516000 | O10020: 0 | P10020: 0 | Q10020: 6151600 | R10020: 67667600 | S10020: 2020
A10021: Nacional | B10021: Agentes Persona Física | C10021: Casa Habitaciòn | D10021: Aguascalientes | E10021: Otro | F10021: 11 | G10021: Ninguno | H10021: 2 | I10021: 26210.76 | J10021: 2517.67 | K10021: 21834.07 | M10021: 8069 | N10021: 278219326 | O10021: 7856054 | P10021: 0 | Q10021: 0 | R10021: 286075380 | S10021: 2020
A10022: Nacional | B10022: Agentes Persona Física | C10022: Casa Habitaciòn | D10022: Aguascalientes | E10022: Otro | F10022: 22 | G10022: Ninguno | H10022: 2 | I10022: 45.76 | J10022: 18.31 | K10022: 45.88 | M10022: 7 | N10022: 0 | O10022: 500000 | P10022: 0 | Q10022: 60000 | R10022: 560000 | S10022: 2020
A10023: Nacional | B10023: Agentes Persona Física | C10023: Casa Habitaciòn | D10023: Aguascalientes | E10023: Otro | F10023: 23 | G10023: Ninguno | H10023: 1 | I10023: 710 | J10023: 710 | K10023: 152 | M10023: 122 | N10023: 200000 | O10023: 1000000 | P10023: 0 | Q10023: 200000 | R10023: 1400000 | S10023: 2020
A10024: Nacional | B10024: Agentes Persona Física | C10024: Casa Habitaciòn | D10024: Aguascalientes | E10024: Otro | F10024: 53 | G10024: Ninguno | H10024: 3 | I10024: 2048 | J10024: 2048 | K10024: 1020 | M10024: 316 | N10024: 274779 | O10024: 1512000 | P10024: 0 | Q10024: 110018 | R10024: 1896797 | S10024: 2020
A10025: Nacional | B10025: Agentes Persona Física | C10025: Casa Habitaciòn | D10025: Aguascalientes | E10025: Microseguro | F10025: 1 | G10025: Ninguno | H10025: 49 | I10025: 2280.6 | J10025: 2235.2 | K10025: 3922.5 | M10025: 319 | N10025: 118943955 | O10025: 19992632 | P10025: 0 | Q10025: 6257337 | R10025: 145193924 | S10025: 2020
... A12628: Nacional | B12628: Otra Forma de Venta | C12628: Casa Habitaciòn | D12628: Mexico | E12628: Microseguro | F12628: 1 | G12628: Ninguno | H12628: 1 | I12628: 0 | J12628: 0 | K12628: 31.98 | M12628: 0 | N12628: 4500000 | O12628: 450000 | P12628: 0 | Q12628: 165000 | R12628: 5115000 | S12628: 2020

Sheet Suma Asegurada
A1: GIRO | B1: ENTIDAD | C1: SUBTIPO DE SEGURO | D1: TIPO PRIMER RIESGO | E1: TIPO DE BIEN | F1: COBERTURA | G1: NÚMERO DE UBICACIONES | H1: SUMA ASEGURADA | I1: SUMA ASEGURADA EXPUESTA | J1: AÑO
A2: Casa Habitaciòn | B2: Puebla | C2: Pymes | D2: Ninguno | E2: Contenidos | F2: Incendio, rayo y explosión | G2: 129 | H2: 458604355 | I2: 457981355 | J2: 2024
A3: Casa Habitaciòn | B3: Hidalgo | C3: Otro | D3: Ninguno | E3: Contenidos | F3: Incendio, rayo y explosión | G3: 4678 | H3: 1611760612 | I3: 1343934692 | J3: 2024
A4: Casa Habitaciòn | B4: Veracruz | C4: Otro | D4: Ninguno | E4: Contenidos | F4: Incendio, rayo y explosión | G4: 12177 | H4: 4747585879 | I4: 3343858244 | J4: 2024
A5: Casa Habitaciòn | B5: San Luis Potosí | C5: Otro | D5: Ninguno | E5: Contenidos | F5: Incendio, rayo y explosión | G5: 2826 | H5: 2322135212 | I5: 1505450436 | J5: 2024
A6: Casa Habitaciòn | B6: Mexico | C6: Negocio gubernamental | D6: Ninguno | E6: Contenidos | F6: Incendio, rayo y explosión | G6: 135 | H6: 725822372 | I6: 725822372 | J6: 2024
A7: Casa Habitaciòn | B7: Jalisco | C7: Pymes | D7: Ninguno | E7: Edificio | F7: Remoción de Escombros | G7: 9 | H7: 668493449 | I7: 668493449 | J7: 2024
A8: Casa Habitaciòn | B8: Baja California | C8: Otro | D8: Ninguno | E8: Edificio | F8: Incendio, rayo y explosión | G8: 21932 | H8: 82076515645 | I8: 55558516802 | J8: 2024
A9: Casa Habitaciòn | B9: Morelos | C9: Negocio gubernamental | D9: Ninguno | E9: Contenidos | F9: Incendio, rayo y explosión | G9: 5 | H9: 20967570 | I9: 20967570 | J9: 2024
A10: Casa Habitaciòn | B10: Oaxaca | C10: Otro | D10: Ninguno | E10: Edificio | F10: Remoción de Escombros | G10: 483 | H10: 202777816 | I10: 143072652 | J10: 2024
A11: Casa Habitaciòn | B11: Ciudad de México | C11: Negocio gubernamental | D11: Ninguno | E11: Contenidos | F11: Incendio, rayo y explosión | G11: 125 | H11: 85657225 | I11: 85657225 | J11: 2024
A12: Casa Habitaciòn | B12: Tamaulipas | C12: Otro | D12: Ninguno | E12: Contenidos | F12: Incendio, rayo y explosión | G12: 6066 | H12: 3763670048 | I12: 2560966745 | J12: 2024
A13: Casa Habitaciòn | B13: Quintana Roo | C13: Negocio gubernamental | D13: Ninguno | E13: Edificio | F13: Incendio, rayo y explosión | G13: 18 | H13: 8031035 | I13: 8031035 | J13: 2024
... A1491: Casa Habitaciòn | B1491: Quintana Roo | C1491: Otro | D1491: Ninguno | E1491: Edificio | F1491: Remoción de Escombros | G1491: 3247 | H1491: 1338552240 | I1491: 985654320 | J1491: 2020

Sheet Siniestros
A1: MONEDA | B1: FORMA DE VENTA | C1: GIRO LA UBICACIÓN | D1: NÚMERO DE NIVELES | E1: TIPO PRIMER RIESGO | F1: ENTIDAD | G1: SUBTIPO DE SEGURO | H1: TIPO DE BIEN | I1: COBERTURA | J1: CAUSA DEL SINIESTRO | K1: NÚMERO DE SINIESTROS | L1: MONTO DE SINIESTRO | M1: GASTO DE AJUSTE | N1: SALVAMENTO | O1: MONTO PAGADO | P1: MONTO DE DEDUCIBLE | Q1: MONTO COASEGURO | R1: RECUPERACION DE TERCEROS | S1: RECUPERACION DE REASEGURO | T1: AÑO
A2: Nacional | B2: Agentes Persona Física | C2: Casa Habitaciòn | D2: 1 | E2: Ninguno | F2: Aguascalientes | G2: Otro | H2: Edificio | I2: Incendio, rayo y explosión | J2: Acción del Agua que no Provenga de las Condiciones Atmosféricas | K2: 1 | L2: 0 | M2: 1870 | N2: 0 | O2: 0 | P2: 0 | Q2: 0 | R2: 0 | S2: 0 | T2: 2024
A3: Nacional | B3: Agentes Persona Física | C3: Casa Habitaciòn | D3: 1 | E3: Ninguno | F3: Aguascalientes | G3: Otro | H3: Contenidos | I3: Incendio, rayo y explosión | J3: Explosión | K3: 1 | L3: 0 | M3: 3423 | N3: 0 | O3: 0 | P3: 0 | Q3: 0 | R3: 0 | S3: 0 | T3: 2024
A4: Nacional | B4: Agentes Persona Física | C4: Casa Habitaciòn | D4: 1 | E4: Ninguno | F4: Aguascalientes | G4: Otro | H4: Contenidos | I4: Incendio, rayo y explosión | J4: Rayo | K4: 1 | L4: -25758.23 | M4: 0 | N4: 0 | O4: 0 | P4: 0 | Q4: 0 | R4: 0 | S4: -12879.12 | T4: 2024
A5: Nacional | B5: Agentes Persona Física | C5: Casa Habitaciòn | D5: 1 | E5: Ninguno | F5: Baja California | G5: Otro | H5: Edificio | I5: Incendio, rayo y explosión | J5: Corto circuito / Electricidad | K5: 3 | L5: 85399 | M5: 7357 | N5: 0 | O5: 86399 | P5: 1000 | Q5: 0 | R5: 0 | S5: 51239.4 | T5: 2024
A6: Nacional | B6: Agentes Persona Física | C6: Casa Habitaciòn | D6: 1 | E6: Ninguno | F6: Baja California | G6: Otro | H6: Edificio | I6: Incendio, rayo y explosión | J6: Incendio por Lluvia | K6: 1 | L6: 0 | M6: 1750 | N6: 0 | O6: 0 | P6: 0 | Q6: 0 | R6: 0 | S6: 0 | T6: 2024
A7: Nacional | B7: Agentes Persona Física | C7: Casa Habitaciòn | D7: 1 | E7: Ninguno | F7: Baja California | G7: Otro | H7: Edificio | I7: Incendio, rayo y explosión | J7: Rayo | K7: 7 | L7: 1092790.4 | M7: 27092 | N7: 0 | O7: 1181995.2 | P7: 0 | Q7: 0 | R7: 9795.69 | S7: 550122.06 | T7: 2024
A8: Nacional | B8: Agentes Persona Física | C8: Casa Habitaciòn | D8: 1 | E8: Ninguno | F8: Baja California | G8: Otro | H8: Edificio | I8: Incendio, rayo y explosión | J8: Roturas de tuberías o sistemas de agua | K8: 2 | L8: 160096.4 | M8: 11964.19 | N8: 0 | O8: 160096.4 | P8: 0 | Q8: 0 | R8: 0 | S8: 96057.84 | T8: 2024
A9: Nacional | B9: Agentes Persona Física | C9: Casa Habitaciòn | D9: 1 | E9: Ninguno | F9: Baja California | G9: Otro | H9: Contenidos | I9: Incendio, rayo y explosión | J9: Corto circuito / Electricidad | K9: 1 | L9: -210.32 | M9: 4000 | N9: 0 | O9: 10384.64 | P9: 0 | Q9: 0 | R9: 0 | S9: 0 | T9: 2024
A10: Nacional | B10: Agentes Persona Física | C10: Casa Habitaciòn | D10: 1 | E10: Ninguno | F10: Baja California | G10: Otro | H10: Contenidos | I10: Incendio, rayo y explosión | J10: Explosión | K10: 1 | L10: 0 | M10: 3423 | N10: 0 | O10: 0 | P10: 0 | Q10: 0 | R10: 0 | S10: 0 | T10: 2024
A11: Nacional | B11: Agentes Persona Física | C11: Casa Habitaciòn | D11: 1 | E11: Ninguno | F11: Baja California | G11: Otro | H11: Contenidos | I11: Incendio, rayo y explosión | J11: Rayo | K11: 2 | L11: 161051 | M11: 0 | N11: 0 | O11: 161051 | P11: 0 | Q11: 0 | R11: 0 | S11: 80525.5 | T11: 2024
A12: Nacional | B12: Agentes Persona Física | C12: Casa Habitaciòn | D12: 1 | E12: Ninguno | F12: Baja California Sur | G12: Otro | H12: Edificio | I12: Incendio, rayo y explosión | J12: Rayo | K12: 2 | L12: -17750.23 | M12: 3469 | N12: 0 | O12: 0 | P12: 0 | Q12: 0 | R12: 0 | S12: -8875.12 | T12: 2024
A13: Nacional | B13: Agentes Persona Física | C13: Casa Habitaciòn | D13: 1 | E13: Ninguno | F13: Coahuila | G13: Otro | H13: Edificio | I13: Incendio, rayo y explosión | J13: Corto circuito / Electricidad | K13: 116 | L13: 4194436.9 | M13: 343118.71 | N13: 0 | O13: 3914738.4 | P13: 157623.47 | Q13: 0 | R13: 0 | S13: 361231.51 | T13: 2024
... A4569: Nacional | B4569: Otros Canales de Venta Masiva | C4569: Casa Habitaciòn | D4569: 1 | E4569: Ninguno | F4569: Nuevo Leon | G4569: Otro | H4569: Contenidos | I4569: Incendio, rayo y explosión | J4569: Incendio por Lluvia | K4569: 1 | L4569: 0 | M4569: 1750 | N4569: 0 | O4569: 0 | P4569: 0 | Q4569: 0 | R4569: 0 | S4569: 0 | T4569: 2021
A4570: Nacional | B4570: Agentes Persona Física | C4570: Casa Habitaciòn | D4570: 1 | E4570: Ninguno | F4570: Mexico | G4570: Otro | H4570: Contenidos | I4570: Incendio, rayo y explosión | J4570: Rayo | K4570: 1 | L4570: -51824 | M4570: 0 | N4570: 0 | O4570: 0 | P4570: 0 | Q4570: 0 | T4570: 2020
A4571: Nacional | B4571: Agentes Persona Física | C4571: Casa Habitaciòn | D4571: 1 | E4571: Ninguno | F4571: Sonora | G4571: Otro | H4571: Edificio | I4571: Incendio, rayo y explosión | J4571: Rayo | K4571: 1 | L4571: -163612 | M4571: 0 | N4571: 0 | O4571: 0 | P4571: 0 | Q4571: 0 | T4571: 2020
A4572: Nacional | B4572: Agentes Persona Física | C4572: Casa Habitaciòn | D4572: 2 | E4572: Ninguno | F4572: Jalisco | G4572: Otro | H4572: Contenidos | I4572: Incendio, rayo y explosión | J4572: Rayo | K4572: 1 | L4572: 0 | M4572: 0 | N4572: -500 | O4572: 0 | P4572: 0 | Q4572: 0 | T4572: 2020
A4573: Nacional | B4573: Red de Sucursales Bancarias | C4573: Casa Habitaciòn | D4573: 1 | E4573: Ninguno | F4573: Nuevo Leon | G4573: Otro | H4573: Contenidos | I4573: Incendio, rayo y explosión | J4573: Rayo | K4573: 1 | L4573: 0 | M4573: 0 | N4573: -1649.85 | O4573: 0 | P4573: 0 | Q4573: 0 | T4573: 2020
A4574: Nacional | B4574: Agentes Persona Física | C4574: Casa Habitaciòn | D4574: 1 | E4574: Ninguno | F4574: Aguascalientes | G4574: Otro | H4574: Contenidos | I4574: Incendio, rayo y explosión | J4574: Actos de Personas Mal Intencionadas | K4574: 1 | L4574: 49750.02 | M4574: 6468.84 | N4574: 0 | O4574: 113417.58 | P4574: 0 | Q4574: 0 | T4574: 2020
A4575: Nacional | B4575: Agentes Persona Física | C4575: Casa Habitaciòn | D4575: 1 | E4575: Ninguno | F4575: Aguascalientes | G4575: Otro | H4575: Contenidos | I4575: Incendio, rayo y explosión | J4575: Rayo | K4575: 1 | L4575: 12316 | M4575: 0 | N4575: 0 | O4575: 0 | P4575: 0 | Q4575: 0 | T4575: 2020
A4576: Nacional | B4576: Agentes Persona Física | C4576: Casa Habitaciòn | D4576: 1 | E4576: Ninguno | F4576: Baja California | G4576: Otro | H4576: Edificio | I4576: Incendio, rayo y explosión | J4576: Corto circuito / Electricidad | K4576: 4 | L4576: 92385.35 | M4576: 8056.04 | N4576: 0 | O4576: 70425.35 | P4576: 0 | Q4576: 0 | T4576: 2020
A4577: Nacional | B4577: Agentes Persona Física | C4577: Casa Habitaciòn | D4577: 1 | E4577: Ninguno | F4577: Baja California | G4577: Otro | H4577: Edificio | I4577: Incendio, rayo y explosión | J4577: Explosión | K4577: 1 | L4577: -15786 | M4577: 3349.14 | N4577: 0 | O4577: 14214 | P4577: 0 | Q4577: 0 | T4577: 2020
A4578: Nacional | B4578: Agentes Persona Física | C4578: Casa Habitaciòn | D4578: 1 | E4578: Ninguno | F4578: Baja California | G4578: Otro | H4578: Edificio | I4578: Incendio, rayo y explosión | J4578: Impacto de Vehículos | K4578: 1 | L4578: 1000 | M4578: 0 | N4578: 0 | O4578: 0 | P4578: 0 | Q4578: 0 | T4578: 2020
A4579: Nacional | B4579: Agentes Persona Física | C4579: Casa Habitaciòn | D4579: 1 | E4579: Ninguno | F4579: Baja California | G4579: Otro | H4579: Edificio | I4579: Incendio, rayo y explosión | J4579: Incendio por Lluvia | K4579: 2 | L4579: 292922.13 | M4579: 20719.16 | N4579: 0 | O4579: 992922.13 | P4579: 0 | Q4579: 0 | T4579: 2020
A4580: Nacional | B4580: Agentes Persona Física | C4580: Casa Habitaciòn | D4580: 1 | E4580: Ninguno | F4580: Baja California | G4580: Otro | H4580: Edificio | I4580: Incendio, rayo y explosión | J4580: Rayo | K4580: 3 | L4580: 75240.38 | M4580: 9150 | N4580: 0 | O4580: 75240.38 | P4580: 0 | Q4580: 0 | T4580: 2020
A4581: Nacional | B4581: Agentes Persona Física | C4581: Casa Habitaciòn | D4581: 1 | E4581: Ninguno | F4581: Baja California | G4581: Otro | H4581: Edificio | I4581: Incendio, rayo y explosión | J4581: Vientos Tempestuosos | K4581: 1 | L4581: 94361.98 | M4581: 7357 | N4581: 0 | O4581: 94361.98 | P4581: 12000 | Q4581: 8578.12 | T4581: 2020
... A5681: Nacional | B5681: Otros Canales de Venta Masiva | C5681: Casa Habitaciòn | D5681: 1 | E5681: Ninguno | F5681: Nuevo Leon | G5681: Microseguro | H5681: Edificio | I5681: Incendio, rayo y explosión | J5681: Rayo | K5681: 1 | L5681: 8010.02 | M5681: 1001.83 | N5681: 0 | O5681: 8010.02 | P5681: 0 | Q5681: 0 | T5681: 2020

Sheet Resumen
C4: NÚMERO DE UBICACIONES | D4: Column Labels
D5: 2020 | G5: 2021 | J5: 2022 | M5: 2023 | P5: 2024 | S5: Total
C6: Coberturas | D6: Contenidos | E6: Contenidos y Edificio | F6: Edificio | G6: Contenidos | H6: Contenidos y Edificio | I6: Edificio | J6: Contenidos | K6: Contenidos y Edificio | L6: Edificio | M6: Contenidos | N6: Contenidos y Edificio | O6: Edificio | P6: Contenidos | Q6: Contenidos y Edificio | R6: Edificio
C7: Gastos Extras para Casa Habitación | D7: 1895 | F7: 2 | G7: 3976 | I7: 2 | J7: 31217 | M7: 5127 | P7: 4320 | S7: 46539
C8: Incendio, rayo y explosión | D8: 673883 | E8: 417 | F8: 674719 | G8: 573259 | H8: 213 | I8: 1266438 | J8: 520319 | K8: 358 | L8: 513813 | M8: 508661 | N8: 317 | O8: 619491 | P8: 429612 | Q8: 350 | R8: 410546 | S8: 6192396
C9: Remoción de Escombros | D9: 215406 | F9: 152352 | G9: 184278 | I9: 123963 | J9: 179010 | L9: 154744 | M9: 149236 | O9: 91828 | P9: 120926 | R9: 64579 | S9: 1436322
C10: Total | D10: 891184 | E10: 417 | F10: 827073 | G10: 761513 | H10: 213 | I10: 1390403 | J10: 730546 | K10: 358 | L10: 668557 | M10: 663024 | N10: 317 | O10: 711319 | P10: 554858 | Q10: 350 | R10: 475125 | S10: 7675257
C14: SUMA ASEGURADA EXPUESTA | D14: Column Labels
D15: 2020 | G15: 2021 | J15: 2022 | M15: 2023 | P15: 2024 | S15: Total
C16: Coberturas | D16: Contenidos | E16: Contenidos y Edificio | F16: Edificio | G16: Contenidos | H16: Contenidos y Edificio | I16: Edificio | J16: Contenidos | K16: Contenidos y Edificio | L16: Edificio | M16: Contenidos | N16: Contenidos y Edificio | O16: Edificio | P16: Contenidos | Q16: Contenidos y Edificio | R16: Edificio
C17: Gastos Extras para Casa Habitación | D17: 95942518 | F17: 995436 | G17: 192352389 | I17: 1023360 | J17: 684736280 | M17: 451708746 | P17: 443882851 | S17: 1870641580
C18: Incendio, rayo y explosión | D18: 47626704609367 | E18: 6149304807 | F18: 82051142970399 | G18: 1290949586620 | H18: 3244809962 | I18: 3039121781033 | J18: 1135985333759 | K18: 8332129337 | L18: 2532936690020 | M18: 607034393380 | N18: 12455496851 | O18: 1790053777913 | P18: 480762741362 | Q18: 17972606512 | R18: 1760420977255 | S18: 142363267208577
C19: Remoción de Escombros | D19: 4679821756459 | F19: 8062079511268 | G19: 11610964686 | I19: 22829632835 | J19: 13558403700 | L19: 42647434780 | M19: 8974201388 | O19: 19132409006 | P19: 11118637918 | R19: 39503160104 | S19: 12911276112144
C20: Total | D20: 52306622308344 | E20: 6149304807 | F20: 90113223477103 | G20: 1302752903695 | H20: 3244809962 | I20: 3061952437228 | J20: 1150228473739 | K20: 8332129337 | L20: 2575584124800 | M20: 616460303514 | N20: 12455496851 | O20: 1809186186919 | P20: 492325262131 | Q20: 17972606512 | R20: 1799924137359 | S20: 155276413962301
C24: SUMA ASEGURADA | D24: Column Labels
D25: 2020 | G25: 2021 | J25: 2022 | M25: 2023 | P25: 2024 | S25: Total
C26: Coberturas | D26: Contenidos | E26: Contenidos y Edificio | F26: Edificio | G26: Contenidos | H26: Contenidos y Edificio | I26: Edificio | J26: Contenidos | K26: Contenidos y Edificio | L26: Edificio | M26: Contenidos | N26: Contenidos y Edificio | O26: Edificio | P26: Contenidos | Q26: Contenidos y Edificio | R26: Edificio
C27: Gastos Extras para Casa Habitación | D27: 99323618 | F27: 995436 | G27: 195416157 | I27: 1023360 | J27: 690110756 | M27: 458519589 | P27: 449263813 | S27: 1894652729
C28: Incendio, rayo y explosión | D28: 1909121102640 | E28: 6024289932 | F28: 2794393914954 | G28: 8058169895874 | H28: 3228233532 | I28: 23644240500688 | J28: 3681765415624 | K28: 8164429259 | L28: 8755821449866 | M28: 741910026232 | N28: 13433523821 | O28: 2318767600649 | P28: 620810531464 | Q28: 22232203505 | R28: 2351357057777 | S28: 54929440175817
C29: Remoción de Escombros | D29: 15979255017 | F29: 32449495055 | G29: 12860693409 | I29: 27814375140 | J29: 15110740079 | L29: 51238063678 | M29: 10601559556 | O29: 25800918313 | P29: 13038531019 | R29: 47791198424 | S29: 252684829690
C30: Total | D30: 1925199681275 | E30: 6024289932 | F30: 2826844405445 | G30: 8071226005440 | H30: 3228233532 | I30: 23672055899188 | J30: 3697566266459 | K30: 8164429259 | L30: 8807059513544 | M30: 752970105377 | N30: 13433523821 | O30: 2344568518962 | P30: 634298326296 | Q30: 22232203505 | R30: 2399148256201 | S30: 55184019658236
C37: MONTO PAGADO | D37: Column Labels
D38: 2020 | G38: 2021 | J38: 2022 | M38: 2023 | O38: 2024 | R38: Total
C39: Coberturas | D39: Contenidos | E39: Contenidos y Edificio | F39: Edificio | G39: Contenidos | H39: Contenidos y Edificio | I39: Edificio | J39: Contenidos | K39: Contenidos y Edificio | L39: Edificio | M39: Contenidos | N39: Edificio | O39: Contenidos | P39: Contenidos y Edificio | Q39: Edificio
C40: Gastos Extras para Casa Habitación | F40: 0 | J40: 0 | L40: 0 | M40: 0 | N40: 0 | R40: 0
C41: Incendio, rayo y explosión | D41: 14152909 | E41: 89604.93 | F41: 39613237 | G41: 41559932 | H41: 78469.8 | I41: 76745014 | J41: 69112735 | K41: 27450 | L41: 77540515 | M41: 12522628 | N41: 66314143 | O41: 18613666 | P41: 0 | Q41: 79179491 | R41: 4.955498e+08
C42: Remoción de Escombros | D42: 21647.5 | F42: 547158.54 | G42: 27600 | I42: 600110.04 | J42: 33580 | L42: 1415858.9 | M42: 164854.7 | N42: 1409319.1 | O42: 191555.49 | Q42: 3608496 | R42: 8020180.3
C43: Total | D43: 14174556 | E43: 89604.93 | F43: 40160396 | G43: 41587532 | H43: 78469.8 | I43: 77345124 | J43: 69146315 | K43: 27450 | L43: 78956374 | M43: 12687482 | N43: 67723463 | O43: 18805222 | P43: 0 | Q43: 82787987 | R43: 5.0356998e+08
C47: MONTO DE SINIESTRO | D47: Column Labels
D48: 2020 | G48: 2021 | J48: 2022 | M48: 2023 | O48: 2024 | R48: Total
C49: Coberturas | D49: Contenidos | E49: Contenidos y Edificio | F49: Edificio | G49: Contenidos | H49: Contenidos y Edificio | I49: Edificio | J49: Contenidos | K49: Contenidos y Edificio | L49: Edificio | M49: Contenidos | N49: Edificio | O49: Contenidos | P49: Contenidos y Edificio | Q49: Edificio
C50: Gastos Extras para Casa Habitación | F50: 0 | J50: 7000 | L50: 3000 | M50: -7000 | N50: -3000 | R50: 0
C51: Incendio, rayo y explosión | D51: 16286686 | E51: -51050.1 | F51: 28931440 | G51: 90820243 | H51: -21530.2 | I51: 1.0399844e+08 | J51: 21179212 | K51: 27450 | L51: 94301269 | M51: 11870158 | N51: 37268776 | O51: 21493858 | P51: 27010 | Q51: 74696252 | R51: 5.0082822e+08
C52: Remoción de Escombros | D52: 21647.5 | F52: 641088.09 | G52: 29567 | I52: 691636.47 | J52: 51030 | L52: 1520598.8 | M52: 283449.7 | N52: 2668707.2 | O52: 267990.49 | Q52: 4030659 | R52: 10206374
C53: Total | D53: 16308334 | E53: -51050.1 | F53: 29572528 | G53: 90849810 | H53: -21530.2 | I53: 1.0469008e+08 | J53: 21237242 | K53: 27450 | L53: 95824868 | M53: 12146608 | N53: 39934484 | O53: 21761849 | P53: 27010 | Q53: 78726911 | R53: 5.1103459e+08
C57: NÚMERO DE SINIESTROS | D57: Column Labels
D58: 2020 | G58: 2021 | J58: 2022 | M58: 2023 | O58: 2024 | R58: Total
C59: Coberturas | D59: Contenidos | E59: Contenidos y Edificio | F59: Edificio | G59: Contenidos | H59: Contenidos y Edificio | I59: Edificio | J59: Contenidos | K59: Contenidos y Edificio | L59: Edificio | M59: Contenidos | N59: Edificio | O59: Contenidos | P59: Contenidos y Edificio | Q59: Edificio
C60: Gastos Extras para Casa Habitación | F60: 1 | J60: 1 | L60: 2 | M60: 1 | N60: 1 | R60: 6
C61: Incendio, rayo y explosión | D61: 701 | E61: 4 | F61: 1448 | G61: 867 | H61: 1 | I61: 1696 | J61: 837 | K61: 1 | L61: 1705 | M61: 933 | N61: 1818 | O61: 976 | P61: 1 | Q61: 2018 | R61: 13006
...

Sheet Sheet1
C4: Frecuencia | D4: Column Labels
D5: 2020 | G5: 2021 | J5: 2022 | M5: 2023 | P5: 2024 | S5: Total
C6: Coberturas | D6: Contenidos | E6: Contenidos y Edificio | F6: Edificio | G6: Contenidos | H6: Contenidos y Edificio | I6: Edificio | J6: Contenidos | K6: Contenidos y Edificio | L6: Edificio | M6: Contenidos | N6: Contenidos y Edificio | O6: Edificio | P6: Contenidos | Q6: Contenidos y Edificio | R6: Edificio
C7: Gastos Extras para Casa Habitación | D7: =IFERROR(Resumen!D60/Resumen!D7,0) -> 0 | E7: =IFERROR(Resumen!E60/Resumen!E7,0) -> 0 | F7: =IFERROR(Resumen!F60/Resumen!F7,0) -> 0.5 | G7: =IFERROR(Resumen!G60/Resumen!G7,0) -> 0 | H7: =IFERROR(Resumen!H60/Resumen!H7,0) -> 0 | I7: =IFERROR(Resumen!I60/Resumen!I7,0) -> 0 | J7: =IFERROR(Resumen!J60/Resumen!J7,0) -> 3.2033828e-05 | K7: =IFERROR(Resumen!K60/Resumen!K7,0) -> 0 | ... M7: =IFERROR(Resumen!M60/Resumen!M7,0) -> 0.00019504584 | N7: 0 | O7: =IFERROR(Resumen!N60/Resumen!O7,0) -> 0 | P7: =IFERROR(Resumen!O60/Resumen!P7,0) -> 0 | Q7: =IFERROR(Resumen!P60/Resumen!Q7,0) -> 0 | R7: =IFERROR(Resumen!Q60/Resumen!R7,0) -> 0 | S7: =SUM(D7:R7) -> 0.50022708
C8: Incendio, rayo y explosión | D8: =IFERROR(Resumen!D61/Resumen!D8,0) -> 0.0010402399 | E8: =IFERROR(Resumen!E61/Resumen!E8,0) -> 0.0095923261 | F8: =IFERROR(Resumen!F61/Resumen!F8,0) -> 0.0021460786 | G8: =IFERROR(Resumen!G61/Resumen!G8,0) -> 0.0015124054 | H8: =IFERROR(Resumen!H61/Resumen!H8,0) -> 0.0046948357 | I8: =IFERROR(Resumen!I61/Resumen!I8,0) -> 0.0013391891 | J8: =IFERROR(Resumen!J61/Resumen!J8,0) -> 0.0016086286 | K8: =IFERROR(Resumen!K61/Resumen!K8,0) -> 0.0027932961 | ... M8: =IFERROR(Resumen!M61/Resumen!M8,0) -> 0.0018342275 | N8: 0 | O8: =IFERROR(Resumen!N61/Resumen!O8,0) -> 0.0029346673 | P8: =IFERROR(Resumen!O61/Resumen!P8,0) -> 0.0022718174 | Q8: =IFERROR(Resumen!P61/Resumen!Q8,0) -> 0.0028571429 | R8: =IFERROR(Resumen!Q61/Resumen!R8,0) -> 0.0049154053 | S8: =SUM(D8:R8) -> 0.042858588
C9: Remoción de Escombros | D9: =IFERROR(Resumen!D62/Resumen!D9,0) -> 9.2847924e-06 | E9: =IFERROR(Resumen!E62/Resumen!E9,0) -> 0 | F9: =IFERROR(Resumen!F62/Resumen!F9,0) -> 0.00024942239 | G9: =IFERROR(Resumen!G62/Resumen!G9,0) -> 1.6279751e-05 | H9: =IFERROR(Resumen!H62/Resumen!H9,0) -> 0 | I9: =IFERROR(Resumen!I62/Resumen!I9,0) -> 0.00029040924 | J9: =IFERROR(Resumen!J62/Resumen!J9,0) -> 2.234512e-05 | K9: =IFERROR(Resumen!K62/Resumen!K9,0) -> 0 | ... M9: =IFERROR(Resumen!M62/Resumen!M9,0) -> 4.6905572e-05 | N9: 0 | O9: =IFERROR(Resumen!N62/Resumen!O9,0) -> 0.00055538616 | P9: =IFERROR(Resumen!O62/Resumen!P9,0) -> 5.7886641e-05 | Q9: =IFERROR(Resumen!P62/Resumen!Q9,0) -> 0 | R9: =IFERROR(Resumen!Q62/Resumen!R9,0) -> 0.0027717989 | S9: =SUM(D9:R9) -> 0.0042265117
C10: Total | D10: =SUM(D7:D9) -> 0.0010495247 | E10: =SUM(E7:E9) -> 0.0095923261 | F10: =SUM(F7:F9) -> 0.5023955 | G10: =SUM(G7:G9) -> 0.0015286851 | H10: =SUM(H7:H9) -> 0.0046948357 | I10: =SUM(I7:I9) -> 0.0016295984 | J10: =SUM(J7:J9) -> 0.0016630075 | K10: =SUM(K7:K9) -> 0.0027932961 | ... S10: =SUM(S7:S9) -> 0.54731218
C14: Severidad Ocurrida | D14: Column Labels
D15: 2020 | G15: 2021 | J15: 2022 | M15: 2023 | O15: 2024 | R15: Total
C16: Coberturas | D16: Contenidos | E16: Contenidos y Edificio | F16: Edificio | G16: Contenidos | H16: Contenidos y Edificio | I16: Edificio | J16: Contenidos | K16: Contenidos y Edificio | L16: Edificio | M16: Contenidos | N16: Edificio | O16: Contenidos | P16: Contenidos y Edificio | Q16: Edificio
C17: Gastos Extras para Casa Habitación | D17: =IFERROR(Resumen!D50/Resumen!D60,0) -> 0 | E17: =IFERROR(Resumen!E50/Resumen!E60,0) -> 0 | F17: =IFERROR(Resumen!F50/Resumen!F60,0) -> 0 | G17: =IFERROR(Resumen!G50/Resumen!G60,0) -> 0 | H17: =IFERROR(Resumen!H50/Resumen!H60,0) -> 0 | I17: =IFERROR(Resumen!I50/Resumen!I60,0) -> 0 | J17: =IFERROR(Resumen!J50/Resumen!J60,0) -> 7000 | K17: =IFERROR(Resumen!K50/Resumen!K60,0) -> 0 | ... Q17: =IFERROR(Resumen!Q50/Resumen!Q60,0) -> 0 | R17: =SUM(D17:Q17) -> -1500
C18: Incendio, rayo y explosión | D18: =IFERROR(Resumen!D51/Resumen!D61,0) -> 23233.504 | E18: =IFERROR(Resumen!E51/Resumen!E61,0) -> -12762.525 | F18: =IFERROR(Resumen!F51/Resumen!F61,0) -> 19980.276 | G18: =IFERROR(Resumen!G51/Resumen!G61,0) -> 104752.3 | H18: =IFERROR(Resumen!H51/Resumen!H61,0) -> -21530.2 | I18: =IFERROR(Resumen!I51/Resumen!I61,0) -> 61319.835 | J18: =IFERROR(Resumen!J51/Resumen!J61,0) -> 25303.718 | K18: =IFERROR(Resumen!K51/Resumen!K61,0) -> 27450 | ... Q18: =IFERROR(Resumen!Q51/Resumen!Q61,0) -> 37014.991 | R18: =SUM(D18:Q18) -> 402325.4
C19: Remoción de Escombros | D19: =IFERROR(Resumen!D52/Resumen!D62,0) -> 10823.75 | E19: =IFERROR(Resumen!E52/Resumen!E62,0) -> 0 | F19: =IFERROR(Resumen!F52/Resumen!F62,0) -> 16870.739 | G19: =IFERROR(Resumen!G52/Resumen!G62,0) -> 9855.6667 | H19: =IFERROR(Resumen!H52/Resumen!H62,0) -> 0 | I19: =IFERROR(Resumen!I52/Resumen!I62,0) -> 19212.124 | J19: =IFERROR(Resumen!J52/Resumen!J62,0) -> 12757.5 | K19: =IFERROR(Resumen!K52/Resumen!K62,0) -> 0 | ... Q19: =IFERROR(Resumen!Q52/Resumen!Q62,0) -> 22517.648 | R19: =SUM(D19:Q19) -> 270660.9
C20: Total | D20: =SUM(D17:D19) -> 34057.254 | E20: =SUM(E17:E19) -> -12762.525 | F20: =SUM(F17:F19) -> 36851.015 | G20: =SUM(G17:G19) -> 114607.97 | H20: =SUM(H17:H19) -> -21530.2 | I20: =SUM(I17:I19) -> 80531.96 | J20: =SUM(J17:J19) -> 45061.218 | K20: =SUM(K17:K19) -> 27450 | ... R20: =SUM(R17:R19) -> 671486.31
C24: Severidad Pagada | D24: Column Labels
D25: 2020 | G25: 2021 | J25: 2022 | M25: 2023 | O25: 2024 | R25: Total
C26: Coberturas | D26: Contenidos | E26: Contenidos y Edificio | F26: Edificio | G26: Contenidos | H26: Contenidos y Edificio | I26: Edificio | J26: Contenidos | K26: Contenidos y Edificio | L26: Edificio | M26: Contenidos | N26: Edificio | O26: Contenidos | P26: Contenidos y Edificio | Q26: Edificio
C27: Gastos Extras para Casa Habitación | D27: =IFERROR(Resumen!D40/Resumen!D60,0) -> 0 | E27: =IFERROR(Resumen!E40/Resumen!E60,0) -> 0 | F27: =IFERROR(Resumen!F40/Resumen!F60,0) -> 0 | G27: =IFERROR(Resumen!G40/Resumen!G60,0) -> 0 | H27: =IFERROR(Resumen!H40/Resumen!H60,0) -> 0 | I27: =IFERROR(Resumen!I40/Resumen!I60,0) -> 0 | J27: =IFERROR(Resumen!J40/Resumen!J60,0) -> 0 | K27: =IFERROR(Resumen!K40/Resumen!K60,0) -> 0 | ... Q27: =IFERROR(Resumen!Q40/Resumen!Q60,0) -> 0 | R27: =SUM(D27:Q27) -> 0
C28: Incendio, rayo y explosión | D28: =IFERROR(Resumen!D41/Resumen!D61,0) -> 20189.599 | E28: =IFERROR(Resumen!E41/Resumen!E61,0) -> 22401.232 | F28: =IFERROR(Resumen!F41/Resumen!F61,0) -> 27357.208 | G28: =IFERROR(Resumen!G41/Resumen!G61,0) -> 47935.332 | H28: =IFERROR(Resumen!H41/Resumen!H61,0) -> 78469.8 | I28: =IFERROR(Resumen!I41/Resumen!I61,0) -> 45250.598 | J28: =IFERROR(Resumen!J41/Resumen!J61,0) -> 82571.965 | K28: =IFERROR(Resumen!K41/Resumen!K61,0) -> 27450 | ... Q28: =IFERROR(Resumen!Q41/Resumen!Q61,0) -> 39236.616 | R28: =SUM(D28:Q28) -> 505310.36
C29: Remoción de Escombros | D29: =IFERROR(Resumen!D42/Resumen!D62,0) -> 10823.75 | E29: =IFERROR(Resumen!E42/Resumen!E62,0) -> 0 | F29: =IFERROR(Resumen!F42/Resumen!F62,0) -> 14398.909 | G29: =IFERROR(Resumen!G42/Resumen!G62,0) -> 9200 | H29: =IFERROR(Resumen!H42/Resumen!H62,0) -> 0 | I29: =IFERROR(Resumen!I42/Resumen!I62,0) -> 16669.723 | J29: =IFERROR(Resumen!J42/Resumen!J62,0) -> 8395 | K29: =IFERROR(Resumen!K42/Resumen!K62,0) -> 0 | ... Q29: =IFERROR(Resumen!Q42/Resumen!Q62,0) -> 20159.196 | R29: =SUM(D29:Q29) -> 202441.62
C30: Total | D30: =SUM(D27:D29) -> 31013.349 | E30: =SUM(E27:E29) -> 22401.232 | F30: =SUM(F27:F29) -> 41756.117 | G30: =SUM(G27:G29) -> 57135.332 | H30: =SUM(H27:H29) -> 78469.8 | I30: =SUM(I27:I29) -> 61920.321 | J30: =SUM(J27:J29) -> 90966.965 | K30: =SUM(K27:K29) -> 27450 | ... R30: =SUM(R27:R29) -> 707751.98
C34: Prima de riesgo pagada | D34: Column Labels
D35: 2020 | G35: 2021 | J35: 2022 | M35: 2023 | P35: 2024 | S35: Total
C36: Coberturas | D36: Contenidos | E36: Contenidos y Edificio | F36: Edificio | G36: Contenidos | H36: Contenidos y Edificio | I36: Edificio | J36: Contenidos | K36: Contenidos y Edificio | L36: Edificio | M36: Contenidos | N36: Contenidos y Edificio | O36: Edificio | P36: Contenidos | Q36: Contenidos y Edificio | R36: Edificio
C37: Gastos Extras para Casa Habitación | D37: =IFERROR(D7*D27,0) -> 0 | E37: =IFERROR(E7*E27,0) -> 0 | F37: =IFERROR(F7*F27,0) -> 0 | G37: =IFERROR(G7*G27,0) -> 0 | H37: =IFERROR(H7*H27,0) -> 0 | I37: =IFERROR(I7*I27,0) -> 0 | J37: =IFERROR(J7*J27,0) -> 0 | K37: =IFERROR(K7*K27,0) -> 0 | ... M37: =IFERROR(M7*M27,0) -> 0 | N37: 0 | O37: =IFERROR(O7*N27,0) -> 0 | P37: =IFERROR(P7*O27,0) -> 0 | Q37: =IFERROR(Q7*P27,0) -> 0 | R37: =IFERROR(R7*Q27,0) -> 0 | S37: =SUM(D37:R37) -> 0
C38: Incendio, rayo y explosión | D38: =IFERROR(D8*D28,0) -> 21.002027 | E38: =IFERROR(E8*E28,0) -> 214.87993 | F38: =IFERROR(F8*F28,0) -> 58.710719 | G38: =IFERROR(G8*G28,0) -> 72.497654 | H38: =IFERROR(H8*H28,0) -> 368.40282 | I38: =IFERROR(I8*I28,0) -> 60.599109 | J38: =IFERROR(J8*J28,0) -> 132.82762 | K38: =IFERROR(K8*K28,0) -> 76.675978 | ... M38: =IFERROR(M8*M28,0) -> 24.618809 | N38: 0 | O38: =IFERROR(O8*N28,0) -> 107.04618 | P38: =IFERROR(P8*O28,0) -> 43.326691 | Q38: =IFERROR(Q8*P28,0) -> 0 | R38: =IFERROR(R8*Q28,0) -> 192.86387 | S38: =SUM(D38:R38) -> 1524.3633
C39: Remoción de Escombros | D39: =IFERROR(D9*D29,0) -> 0.10049627 | E39: =IFERROR(E9*E29,0) -> 0 | F39: =IFERROR(F9*F29,0) -> 3.5914103 | G39: =IFERROR(G9*G29,0) -> 0.14977371 | H39: =IFERROR(H9*H29,0) -> 0 | I39: =IFERROR(I9*I29,0) -> 4.8410416 | J39: =IFERROR(J9*J29,0) -> 0.18758729 | K39: =IFERROR(K9*K29,0) -> 0 | ... R39: =IFERROR(R9*R29,0) -> 561.12745 | S39: =SUM(D39:R39) -> 595.45028
C40: Total | D40: =SUM(D37:D39) -> 21.102523 | E40: =SUM(E37:E39) -> 214.87993 | F40: =SUM(F37:F39) -> 62.302129 | G40: =SUM(G37:G39) -> 72.647427 | H40: =SUM(H37:H39) -> 368.40282 | I40: =SUM(I37:I39) -> 65.44015 | J40: =SUM(J37:J39) -> 133.01521 | K40: =SUM(K37:K39) -> 76.675978 | ... S40: =SUM(S37:S39) -> 2119.8136
C44: Prima de riesgo ocurrida | D44: Column Labels
D45: 2020 | G45: 2021 | J45: 2022 | M45: 2023 | P45: 2024 | S45: Total
C46: Coberturas | D46: Contenidos | E46: Contenidos y Edificio | F46: Edificio | G46: Contenidos | H46: Contenidos y Edificio | I46: Edificio | J46: Contenidos | K46: Contenidos y Edificio | L46: Edificio | M46: Contenidos | N46: Contenidos y Edificio | O46: Edificio | P46: Contenidos | Q46: Contenidos y Edificio | R46: Edificio
C47: Gastos Extras para Casa Habitación | D47: =IFERROR(D7*D17,0) -> 0 | E47: =IFERROR(E7*E17,0) -> 0 | F47: =IFERROR(F7*F17,0) -> 0 | G47: =IFERROR(G7*G17,0) -> 0 | H47: =IFERROR(H7*H17,0) -> 0 | I47: =IFERROR(I7*I17,0) -> 0 | J47: =IFERROR(J7*J17,0) -> 0.22423679 | K47: =IFERROR(K7*K17,0) -> 0 | ... M47: =IFERROR(M7*M17,0) -> -1.3653209 | N47: 0 | O47: =IFERROR(O7*N17,0) -> 0 | P47: =IFERROR(P7*O17,0) -> 0 | Q47: =IFERROR(Q7*P17,0) -> 0 | R47: =IFERROR(R7*Q17,0) -> 0 | S47: =SUM(D47:R47) -> -1.1410841
C48: Incendio, rayo y explosión | D48: =IFERROR(D8*D18,0) -> 24.168418 | E48: =IFERROR(E8*E18,0) -> -122.4223 | F48: =IFERROR(F8*F18,0) -> 42.879243 | G48: =IFERROR(G8*G18,0) -> 158.42794 | H48: =IFERROR(H8*H18,0) -> -101.08075 | I48: =IFERROR(I8*I18,0) -> 82.118857 | J48: =IFERROR(J8*J18,0) -> 40.704283 | K48: =IFERROR(K8*K18,0) -> 76.675978 | ... M48: =IFERROR(M8*M18,0) -> 23.336089 | N48: 0 | O48: =IFERROR(O8*N18,0) -> 60.160319 | P48: =IFERROR(P8*O18,0) -> 50.030861 | Q48: =IFERROR(Q8*P18,0) -> 77.171429 | R48: =IFERROR(R8*Q18,0) -> 181.94368 | S48: =SUM(D48:R48) -> 777.64632
C49: Remoción de Escombros | D49: =IFERROR(D9*D19,0) -> 0.10049627 | E49: =IFERROR(E9*E19,0) -> 0 | F49: =IFERROR(F9*F19,0) -> 4.2079401 | G49: =IFERROR(G9*G19,0) -> 0.1604478 | H49: =IFERROR(H9*H19,0) -> 0 | I49: =IFERROR(I9*I19,0) -> 5.5793783 | J49: =IFERROR(J9*J19,0) -> 0.28506787 | K49: =IFERROR(K9*K19,0) -> 0 | ... M49: =IFERROR(M9*M19,0) -> 1.8993386 | N49: =IFERROR(N19*N39,0) -> 0 | O49: =IFERROR(O9*N19,0) -> 29.062021 | P49: =IFERROR(P9*O19,0) -> 2.2161528 | Q49: =IFERROR(Q9*P19,0) -> 0 | R49: =IFERROR(R9*Q19,0) -> 62.414391 | S49: =SUM(D49:R49) -> 115.75178
C50: Total | D50: =SUM(D47:D49) -> 24.268914 | E50: =SUM(E47:E49) -> -122.4223 | F50: =SUM(F47:F49) -> 47.087183 | G50: =SUM(G47:G49) -> 158.58839 | H50: =SUM(H47:H49) -> -101.08075 | I50: =SUM(I47:I49) -> 87.698235 | J50: =SUM(J47:J49) -> 41.213588 | K50: =SUM(K47:K49) -> 76.675978 | ... S50: =SUM(S47:S49) -> 892.25702
C54: Cuota de Riesgo Ocurrida | D54: Column Labels
D55: 2020 | G55: 2021 | J55: 2022 | M55: 2023 | P55: 2024 | S55: Total
C56: Coberturas | D56: Contenidos | E56: Contenidos y Edificio | F56: Edificio | G56: Contenidos | H56: Contenidos y Edificio | I56: Edificio | J56: Contenidos | K56: Contenidos y Edificio | L56: Edificio | M56: Contenidos | N56: Contenidos y Edificio | O56: Edificio | P56: Contenidos | Q56: Contenidos y Edificio | R56: Edificio
C57: Gastos Extras para Casa Habitación | D57: =IFERROR(Sheet1!D17/Resumen!D17 * 1000,0) -> 0 | E57: =IFERROR(Sheet1!E17/Resumen!E17 * 1000,0) -> 0 | F57: =IFERROR(Sheet1!F17/Resumen!F17 * 1000,0) -> 0 | G57: =IFERROR(Sheet1!G17/Resumen!G17 * 1000,0) -> 0 | H57: =IFERROR(Sheet1!H17/Resumen!H17 * 1000,0) -> 0 | I57: =IFERROR(Sheet1!I17/Resumen!I17 * 1000,0) -> 0 | J57: =IFERROR(Sheet1!J17/Resumen!J17 * 1000,0) -> 0.010222914 | K57: =IFERROR(Sheet1!K17/Resumen!K17 * 1000,0) -> 0 | ... M57: =IFERROR(Sheet1!M17/Resumen!M17 * 1000,0) -> -0.015496711 | N57: 0 | O57: =IFERROR(N17/Resumen!O17 * 1000,0) -> 0 | P57: =IFERROR(O17/Resumen!P17 * 1000,0) -> 0 | Q57: =IFERROR(P17/Resumen!Q17 * 1000,0) -> 0 | R57: =IFERROR(Q17/Resumen!R17 * 1000,0) -> 0 | S57: =SUM(D57:R57) -> -0.0052737974
C58: Incendio, rayo y explosión | D58: =IFERROR(Sheet1!D18/Resumen!D18 * 1000,0) -> 4.8782514e-07 | E58: =IFERROR(Sheet1!E18/Resumen!E18 * 1000,0) -> -0.0020754419 | F58: =IFERROR(Sheet1!F18/Resumen!F18 * 1000,0) -> 2.4351003e-07 | G58: =IFERROR(Sheet1!G18/Resumen!G18 * 1000,0) -> 8.1143602e-05 | H58: =IFERROR(Sheet1!H18/Resumen!H18 * 1000,0) -> -0.006635273 | I58: =IFERROR(Sheet1!I18/Resumen!I18 * 1000,0) -> 2.0176827e-05 | J58: =IFERROR(Sheet1!J18/Resumen!J18 * 1000,0) -> 2.2274687e-05 | K58: =IFERROR(Sheet1!K18/Resumen!K18 * 1000,0) -> 0.003294476 | ... M58: =IFERROR(Sheet1!M18/Resumen!M18 * 1000,0) -> 2.0958566e-05 | N58: 0 | O58: =IFERROR(N18/Resumen!O18 * 1000,0) -> 1.1452101e-05 | P58: =IFERROR(O18/Resumen!P18 * 1000,0) -> 4.5807202e-05 | Q58: =IFERROR(P18/Resumen!Q18 * 1000,0) -> 0.0015028427 | R58: =IFERROR(Q18/Resumen!R18 * 1000,0) -> 2.1026216e-05 | S58: =SUM(D58:R58) -> -0.00366799
...
